Workbook

Sheet Voti
A1: Nome | B1: Voto | C1: Gf | D1: Gs | E1: Rp | F1: Rs | G1: Rf | H1: Au | I1: Amm | J1: Esp | K1: Ass | L1: fantavoto
A2: Svilar | B2: =IFERROR(INDEX(Fantacalcio!D:D, MATCH($A2, Fantacalcio!$C:$C, 0)), 0) -> 0 | C2: =IFERROR(INDEX(Fantacalcio!E:E, MATCH($A2, Fantacalcio!$C:$C, 0)), 0) -> 0 | D2: =IFERROR(INDEX(Fantacalcio!F:F, MATCH($A2, Fantacalcio!$C:$C, 0)), 0) -> 0 | E2: =IFERROR(INDEX(Fantacalcio!G:G, MATCH($A2, Fantacalcio!$C:$C, 0)), 0) -> 0 | F2: =IFERROR(INDEX(Fantacalcio!H:H, MATCH($A2, Fantacalcio!$C:$C, 0)), 0) -> 0 | G2: =IFERROR(INDEX(Fantacalcio!I:I, MATCH($A2, Fantacalcio!$C:$C, 0)), 0) -> 0 | H2: =IFERROR(INDEX(Fantacalcio!J:J, MATCH($A2, Fantacalcio!$C:$C, 0)), 0) -> 0 | I2: =IFERROR(INDEX(Fantacalcio!K:K, MATCH($A2, Fantacalcio!$C:$C, 0)), 0) -> 0 | J2: =IFERROR(INDEX(Fantacalcio!L:L, MATCH($A2, Fantacalcio!$C:$C, 0)), 0) -> 0 | K2: =IFERROR(INDEX(Fantacalcio!M:M, MATCH($A2, Fantacalcio!$C:$C, 0)), 0) -> 0 | L2: =B2+(C2*3)-D2+(E2*3)-(F2*3)+(G2*3)-(H2*2)-(IF(I2=1, 0.5, 0))-J2+K2 -> 0
A3: Carnesecchi | B3: =IFERROR(INDEX(Fantacalcio!D:D, MATCH($A3, Fantacalcio!$C:$C, 0)), 0) -> 6 | C3: =IFERROR(INDEX(Fantacalcio!E:E, MATCH($A3, Fantacalcio!$C:$C, 0)), 0) -> 0 | D3: =IFERROR(INDEX(Fantacalcio!F:F, MATCH($A3, Fantacalcio!$C:$C, 0)), 0) -> 1 | E3: =IFERROR(INDEX(Fantacalcio!G:G, MATCH($A3, Fantacalcio!$C:$C, 0)), 0) -> 0 | F3: =IFERROR(INDEX(Fantacalcio!H:H, MATCH($A3, Fantacalcio!$C:$C, 0)), 0) -> 0 | G3: =IFERROR(INDEX(Fantacalcio!I:I, MATCH($A3, Fantacalcio!$C:$C, 0)), 0) -> 0 | H3: =IFERROR(INDEX(Fantacalcio!J:J, MATCH($A3, Fantacalcio!$C:$C, 0)), 0) -> 0 | I3: =IFERROR(INDEX(Fantacalcio!K:K, MATCH($A3, Fantacalcio!$C:$C, 0)), 0) -> 0 | J3: =IFERROR(INDEX(Fantacalcio!L:L, MATCH($A3, Fantacalcio!$C:$C, 0)), 0) -> 0 | K3: =IFERROR(INDEX(Fantacalcio!M:M, MATCH($A3, Fantacalcio!$C:$C, 0)), 0) -> 0 | L3: =B3+(C3*3)-D3+(E3*3)-(F3*3)+(G3*3)-(H3*2)-(IF(I3=1, 0.5, 0))-J3+K3 -> 5
A4: Martinez Jo. | B4: =IFERROR(INDEX(Fantacalcio!D:D, MATCH($A4, Fantacalcio!$C:$C, 0)), 0) -> 6 | C4: =IFERROR(INDEX(Fantacalcio!E:E, MATCH($A4, Fantacalcio!$C:$C, 0)), 0) -> 0 | D4: =IFERROR(INDEX(Fantacalcio!F:F, MATCH($A4, Fantacalcio!$C:$C, 0)), 0) -> 0 | E4: =IFERROR(INDEX(Fantacalcio!G:G, MATCH($A4, Fantacalcio!$C:$C, 0)), 0) -> 0 | F4: =IFERROR(INDEX(Fantacalcio!H:H, MATCH($A4, Fantacalcio!$C:$C, 0)), 0) -> 0 | G4: =IFERROR(INDEX(Fantacalcio!I:I, MATCH($A4, Fantacalcio!$C:$C, 0)), 0) -> 0 | H4: =IFERROR(INDEX(Fantacalcio!J:J, MATCH($A4, Fantacalcio!$C:$C, 0)), 0) -> 0 | I4: =IFERROR(INDEX(Fantacalcio!K:K, MATCH($A4, Fantacalcio!$C:$C, 0)), 0) -> 0 | J4: =IFERROR(INDEX(Fantacalcio!L:L, MATCH($A4, Fantacalcio!$C:$C, 0)), 0) -> 0 | K4: =IFERROR(INDEX(Fantacalcio!M:M, MATCH($A4, Fantacalcio!$C:$C, 0)), 0) -> 0 | L4: =B4+(C4*3)-D4+(E4*3)-(F4*3)+(G4*3)-(H4*2)-(IF(I4=1, 0.5, 0))-J4+K4 -> 6
A5: Vicario | B5: =IFERROR(INDEX(Fantacalcio!D:D, MATCH($A5, Fantacalcio!$C:$C, 0)), 0) -> 6 | C5: =IFERROR(INDEX(Fantacalcio!E:E, MATCH($A5, Fantacalcio!$C:$C, 0)), 0) -> 0 | D5: =IFERROR(INDEX(Fantacalcio!F:F, MATCH($A5, Fantacalcio!$C:$C, 0)), 0) -> 1 | E5: =IFERROR(INDEX(Fantacalcio!G:G, MATCH($A5, Fantacalcio!$C:$C, 0)), 0) -> 0 | F5: =IFERROR(INDEX(Fantacalcio!H:H, MATCH($A5, Fantacalcio!$C:$C, 0)), 0) -> 0 | G5: =IFERROR(INDEX(Fantacalcio!I:I, MATCH($A5, Fantacalcio!$C:$C, 0)), 0) -> 0 | H5: =IFERROR(INDEX(Fantacalcio!J:J, MATCH($A5, Fantacalcio!$C:$C, 0)), 0) -> 0 | I5: =IFERROR(INDEX(Fantacalcio!K:K, MATCH($A5, Fantacalcio!$C:$C, 0)), 0) -> 0 | J5: =IFERROR(INDEX(Fantacalcio!L:L, MATCH($A5, Fantacalcio!$C:$C, 0)), 0) -> 0 | K5: =IFERROR(INDEX(Fantacalcio!M:M, MATCH($A5, Fantacalcio!$C:$C, 0)), 0) -> 0 | L5: =B5+(C5*3)-D5+(E5*3)-(F5*3)+(G5*3)-(H5*2)-(IF(I5=1, 0.5, 0))-J5+K5 -> 5
A6: Butez | B6: =IFERROR(INDEX(Fantacalcio!D:D, MATCH($A6, Fantacalcio!$C:$C, 0)), 0) -> 6 | C6: =IFERROR(INDEX(Fantacalcio!E:E, MATCH($A6, Fantacalcio!$C:$C, 0)), 0) -> 0 | D6: =IFERROR(INDEX(Fantacalcio!F:F, MATCH($A6, Fantacalcio!$C:$C, 0)), 0) -> 0 | E6: =IFERROR(INDEX(Fantacalcio!G:G, MATCH($A6, Fantacalcio!$C:$C, 0)), 0) -> 0 | F6: =IFERROR(INDEX(Fantacalcio!H:H, MATCH($A6, Fantacalcio!$C:$C, 0)), 0) -> 0 | G6: =IFERROR(INDEX(Fantacalcio!I:I, MATCH($A6, Fantacalcio!$C:$C, 0)), 0) -> 0 | H6: =IFERROR(INDEX(Fantacalcio!J:J, MATCH($A6, Fantacalcio!$C:$C, 0)), 0) -> 0 | I6: =IFERROR(INDEX(Fantacalcio!K:K, MATCH($A6, Fantacalcio!$C:$C, 0)), 0) -> 0 | J6: =IFERROR(INDEX(Fantacalcio!L:L, MATCH($A6, Fantacalcio!$C:$C, 0)), 0) -> 0 | K6: =IFERROR(INDEX(Fantacalcio!M:M, MATCH($A6, Fantacalcio!$C:$C, 0)), 0) -> 0 | L6: =B6+(C6*3)-D6+(E6*3)-(F6*3)+(G6*3)-(H6*2)-(IF(I6=1, 0.5, 0))-J6+K6 -> 6
A7: Maignan | B7: =IFERROR(INDEX(Fantacalcio!D:D, MATCH($A7, Fantacalcio!$C:$C, 0)), 0) -> 6.5 | C7: =IFERROR(INDEX(Fantacalcio!E:E, MATCH($A7, Fantacalcio!$C:$C, 0)), 0) -> 0 | D7: =IFERROR(INDEX(Fantacalcio!F:F, MATCH($A7, Fantacalcio!$C:$C, 0)), 0) -> 1 | E7: =IFERROR(INDEX(Fantacalcio!G:G, MATCH($A7, Fantacalcio!$C:$C, 0)), 0) -> 0 | F7: =IFERROR(INDEX(Fantacalcio!H:H, MATCH($A7, Fantacalcio!$C:$C, 0)), 0) -> 0 | G7: =IFERROR(INDEX(Fantacalcio!I:I, MATCH($A7, Fantacalcio!$C:$C, 0)), 0) -> 0 | H7: =IFERROR(INDEX(Fantacalcio!J:J, MATCH($A7, Fantacalcio!$C:$C, 0)), 0) -> 0 | I7: =IFERROR(INDEX(Fantacalcio!K:K, MATCH($A7, Fantacalcio!$C:$C, 0)), 0) -> 0 | J7: =IFERROR(INDEX(Fantacalcio!L:L, MATCH($A7, Fantacalcio!$C:$C, 0)), 0) -> 0 | K7: =IFERROR(INDEX(Fantacalcio!M:M, MATCH($A7, Fantacalcio!$C:$C, 0)), 0) -> 0 | L7: =B7+(C7*3)-D7+(E7*3)-(F7*3)+(G7*3)-(H7*2)-(IF(I7=1, 0.5, 0))-J7+K7 -> 5.5
A8: Caprile | B8: =IFERROR(INDEX(Fantacalcio!D:D, MATCH($A8, Fantacalcio!$C:$C, 0)), 0) -> 7 | C8: =IFERROR(INDEX(Fantacalcio!E:E, MATCH($A8, Fantacalcio!$C:$C, 0)), 0) -> 0 | D8: =IFERROR(INDEX(Fantacalcio!F:F, MATCH($A8, Fantacalcio!$C:$C, 0)), 0) -> 1 | E8: =IFERROR(INDEX(Fantacalcio!G:G, MATCH($A8, Fantacalcio!$C:$C, 0)), 0) -> 0 | F8: =IFERROR(INDEX(Fantacalcio!H:H, MATCH($A8, Fantacalcio!$C:$C, 0)), 0) -> 0 | G8: =IFERROR(INDEX(Fantacalcio!I:I, MATCH($A8, Fantacalcio!$C:$C, 0)), 0) -> 0 | H8: =IFERROR(INDEX(Fantacalcio!J:J, MATCH($A8, Fantacalcio!$C:$C, 0)), 0) -> 0 | I8: =IFERROR(INDEX(Fantacalcio!K:K, MATCH($A8, Fantacalcio!$C:$C, 0)), 0) -> 0 | J8: =IFERROR(INDEX(Fantacalcio!L:L, MATCH($A8, Fantacalcio!$C:$C, 0)), 0) -> 0 | K8: =IFERROR(INDEX(Fantacalcio!M:M, MATCH($A8, Fantacalcio!$C:$C, 0)), 0) -> 0 | L8: =B8+(C8*3)-D8+(E8*3)-(F8*3)+(G8*3)-(H8*2)-(IF(I8=1, 0.5, 0))-J8+K8 -> 6
A9: Mandas | B9: =IFERROR(INDEX(Fantacalcio!D:D, MATCH($A9, Fantacalcio!$C:$C, 0)), 0) -> 6.5 | C9: =IFERROR(INDEX(Fantacalcio!E:E, MATCH($A9, Fantacalcio!$C:$C, 0)), 0) -> 0 | D9: =IFERROR(INDEX(Fantacalcio!F:F, MATCH($A9, Fantacalcio!$C:$C, 0)), 0) -> 1 | E9: =IFERROR(INDEX(Fantacalcio!G:G, MATCH($A9, Fantacalcio!$C:$C, 0)), 0) -> 0 | F9: =IFERROR(INDEX(Fantacalcio!H:H, MATCH($A9, Fantacalcio!$C:$C, 0)), 0) -> 0 | G9: =IFERROR(INDEX(Fantacalcio!I:I, MATCH($A9, Fantacalcio!$C:$C, 0)), 0) -> 0 | H9: =IFERROR(INDEX(Fantacalcio!J:J, MATCH($A9, Fantacalcio!$C:$C, 0)), 0) -> 0 | I9: =IFERROR(INDEX(Fantacalcio!K:K, MATCH($A9, Fantacalcio!$C:$C, 0)), 0) -> 0 | J9: =IFERROR(INDEX(Fantacalcio!L:L, MATCH($A9, Fantacalcio!$C:$C, 0)), 0) -> 0 | K9: =IFERROR(INDEX(Fantacalcio!M:M, MATCH($A9, Fantacalcio!$C:$C, 0)), 0) -> 0 | L9: =B9+(C9*3)-D9+(E9*3)-(F9*3)+(G9*3)-(H9*2)-(IF(I9=1, 0.5, 0))-J9+K9 -> 5.5
A10: Meret | B10: =IFERROR(INDEX(Fantacalcio!D:D, MATCH($A10, Fantacalcio!$C:$C, 0)), 0) -> 6 | C10: =IFERROR(INDEX(Fantacalcio!E:E, MATCH($A10, Fantacalcio!$C:$C, 0)), 0) -> 0 | D10: =IFERROR(INDEX(Fantacalcio!F:F, MATCH($A10, Fantacalcio!$C:$C, 0)), 0) -> 0 | E10: =IFERROR(INDEX(Fantacalcio!G:G, MATCH($A10, Fantacalcio!$C:$C, 0)), 0) -> 0 | F10: =IFERROR(INDEX(Fantacalcio!H:H, MATCH($A10, Fantacalcio!$C:$C, 0)), 0) -> 0 | G10: =IFERROR(INDEX(Fantacalcio!I:I, MATCH($A10, Fantacalcio!$C:$C, 0)), 0) -> 0 | H10: =IFERROR(INDEX(Fantacalcio!J:J, MATCH($A10, Fantacalcio!$C:$C, 0)), 0) -> 0 | I10: =IFERROR(INDEX(Fantacalcio!K:K, MATCH($A10, Fantacalcio!$C:$C, 0)), 0) -> 0 | J10: =IFERROR(INDEX(Fantacalcio!L:L, MATCH($A10, Fantacalcio!$C:$C, 0)), 0) -> 0 | K10: =IFERROR(INDEX(Fantacalcio!M:M, MATCH($A10, Fantacalcio!$C:$C, 0)), 0) -> 0 | L10: =B10+(C10*3)-D10+(E10*3)-(F10*3)+(G10*3)-(H10*2)-(IF(I10=1, 0.5, 0))-J10+K10 -> 6
A11: Skorupski | B11: =IFERROR(INDEX(Fantacalcio!D:D, MATCH($A11, Fantacalcio!$C:$C, 0)), 0) -> 0 | C11: =IFERROR(INDEX(Fantacalcio!E:E, MATCH($A11, Fantacalcio!$C:$C, 0)), 0) -> 0 | D11: =IFERROR(INDEX(Fantacalcio!F:F, MATCH($A11, Fantacalcio!$C:$C, 0)), 0) -> 0 | E11: =IFERROR(INDEX(Fantacalcio!G:G, MATCH($A11, Fantacalcio!$C:$C, 0)), 0) -> 0 | F11: =IFERROR(INDEX(Fantacalcio!H:H, MATCH($A11, Fantacalcio!$C:$C, 0)), 0) -> 0 | G11: =IFERROR(INDEX(Fantacalcio!I:I, MATCH($A11, Fantacalcio!$C:$C, 0)), 0) -> 0 | H11: =IFERROR(INDEX(Fantacalcio!J:J, MATCH($A11, Fantacalcio!$C:$C, 0)), 0) -> 0 | I11: =IFERROR(INDEX(Fantacalcio!K:K, MATCH($A11, Fantacalcio!$C:$C, 0)), 0) -> 0 | J11: =IFERROR(INDEX(Fantacalcio!L:L, MATCH($A11, Fantacalcio!$C:$C, 0)), 0) -> 0 | K11: =IFERROR(INDEX(Fantacalcio!M:M, MATCH($A11, Fantacalcio!$C:$C, 0)), 0) -> 0 | L11: =B11+(C11*3)-D11+(E11*3)-(F11*3)+(G11*3)-(H11*2)-(IF(I11=1, 0.5, 0))-J11+K11 -> 0
A12: De Gea | B12: =IFERROR(INDEX(Fantacalcio!D:D, MATCH($A12, Fantacalcio!$C:$C, 0)), 0) -> 5.5 | C12: =IFERROR(INDEX(Fantacalcio!E:E, MATCH($A12, Fantacalcio!$C:$C, 0)), 0) -> 0 | D12: =IFERROR(INDEX(Fantacalcio!F:F, MATCH($A12, Fantacalcio!$C:$C, 0)), 0) -> 2 | E12: =IFERROR(INDEX(Fantacalcio!G:G, MATCH($A12, Fantacalcio!$C:$C, 0)), 0) -> 0 | F12: =IFERROR(INDEX(Fantacalcio!H:H, MATCH($A12, Fantacalcio!$C:$C, 0)), 0) -> 0 | G12: =IFERROR(INDEX(Fantacalcio!I:I, MATCH($A12, Fantacalcio!$C:$C, 0)), 0) -> 0 | H12: =IFERROR(INDEX(Fantacalcio!J:J, MATCH($A12, Fantacalcio!$C:$C, 0)), 0) -> 0 | I12: =IFERROR(INDEX(Fantacalcio!K:K, MATCH($A12, Fantacalcio!$C:$C, 0)), 0) -> 0 | J12: =IFERROR(INDEX(Fantacalcio!L:L, MATCH($A12, Fantacalcio!$C:$C, 0)), 0) -> 0 | K12: =IFERROR(INDEX(Fantacalcio!M:M, MATCH($A12, Fantacalcio!$C:$C, 0)), 0) -> 0 | L12: =B12+(C12*3)-D12+(E12*3)-(F12*3)+(G12*3)-(H12*2)-(IF(I12=1, 0.5, 0))-J12+K12 -> 3.5
A13: Okoye | B13: =IFERROR(INDEX(Fantacalcio!D:D, MATCH($A13, Fantacalcio!$C:$C, 0)), 0) -> 4.5 | C13: =IFERROR(INDEX(Fantacalcio!E:E, MATCH($A13, Fantacalcio!$C:$C, 0)), 0) -> 0 | D13: =IFERROR(INDEX(Fantacalcio!F:F, MATCH($A13, Fantacalcio!$C:$C, 0)), 0) -> 2 | E13: =IFERROR(INDEX(Fantacalcio!G:G, MATCH($A13, Fantacalcio!$C:$C, 0)), 0) -> 0 | F13: =IFERROR(INDEX(Fantacalcio!H:H, MATCH($A13, Fantacalcio!$C:$C, 0)), 0) -> 0 | G13: =IFERROR(INDEX(Fantacalcio!I:I, MATCH($A13, Fantacalcio!$C:$C, 0)), 0) -> 0 | H13: =IFERROR(INDEX(Fantacalcio!J:J, MATCH($A13, Fantacalcio!$C:$C, 0)), 0) -> 0 | I13: =IFERROR(INDEX(Fantacalcio!K:K, MATCH($A13, Fantacalcio!$C:$C, 0)), 0) -> 0 | J13: =IFERROR(INDEX(Fantacalcio!L:L, MATCH($A13, Fantacalcio!$C:$C, 0)), 0) -> 0 | K13: =IFERROR(INDEX(Fantacalcio!M:M, MATCH($A13, Fantacalcio!$C:$C, 0)), 0) -> 0 | L13: =B13+(C13*3)-D13+(E13*3)-(F13*3)+(G13*3)-(H13*2)-(IF(I13=1, 0.5, 0))-J13+K13 -> 2.5
... A88: Miranda J. | B88: =IFERROR(INDEX(Fantacalcio!D:D, MATCH($A88, Fantacalcio!$C:$C, 0)), 0) -> 6.5 | C88: =IFERROR(INDEX(Fantacalcio!E:E, MATCH($A88, Fantacalcio!$C:$C, 0)), 0) -> 0 | D88: =IFERROR(INDEX(Fantacalcio!F:F, MATCH($A88, Fantacalcio!$C:$C, 0)), 0) -> 0 | E88: =IFERROR(INDEX(Fantacalcio!G:G, MATCH($A88, Fantacalcio!$C:$C, 0)), 0) -> 0 | F88: =IFERROR(INDEX(Fantacalcio!H:H, MATCH($A88, Fantacalcio!$C:$C, 0)), 0) -> 0 | G88: =IFERROR(INDEX(Fantacalcio!I:I, MATCH($A88, Fantacalcio!$C:$C, 0)), 0) -> 0 | H88: =IFERROR(INDEX(Fantacalcio!J:J, MATCH($A88, Fantacalcio!$C:$C, 0)), 0) -> 0 | I88: =IFERROR(INDEX(Fantacalcio!K:K, MATCH($A88, Fantacalcio!$C:$C, 0)), 0) -> 0 | J88: =IFERROR(INDEX(Fantacalcio!L:L, MATCH($A88, Fantacalcio!$C:$C, 0)), 0) -> 0 | K88: =IFERROR(INDEX(Fantacalcio!M:M, MATCH($A88, Fantacalcio!$C:$C, 0)), 0) -> 0 | L88: =B88+(C88*3)-D88+(E88*3)-(F88*3)+(G88*3)-(H88*2)-(IF(I88=1, 0.5, 0))-J88+K88 -> 6.5
A89: Dodò | B89: 6 | C89: =IFERROR(INDEX(Fantacalcio!E:E, MATCH($A89, Fantacalcio!$C:$C, 0)), 0) -> 0 | D89: =IFERROR(INDEX(Fantacalcio!F:F, MATCH($A89, Fantacalcio!$C:$C, 0)), 0) -> 0 | E89: =IFERROR(INDEX(Fantacalcio!G:G, MATCH($A89, Fantacalcio!$C:$C, 0)), 0) -> 0 | F89: =IFERROR(INDEX(Fantacalcio!H:H, MATCH($A89, Fantacalcio!$C:$C, 0)), 0) -> 0 | G89: =IFERROR(INDEX(Fantacalcio!I:I, MATCH($A89, Fantacalcio!$C:$C, 0)), 0) -> 0 | H89: =IFERROR(INDEX(Fantacalcio!J:J, MATCH($A89, Fantacalcio!$C:$C, 0)), 0) -> 0 | I89: =IFERROR(INDEX(Fantacalcio!K:K, MATCH($A89, Fantacalcio!$C:$C, 0)), 0) -> 0 | J89: =IFERROR(INDEX(Fantacalcio!L:L, MATCH($A89, Fantacalcio!$C:$C, 0)), 0) -> 0 | K89: =IFERROR(INDEX(Fantacalcio!M:M, MATCH($A89, Fantacalcio!$C:$C, 0)), 0) -> 0 | L89: =B89+(C89*3)-D89+(E89*3)-(F89*3)+(G89*3)-(H89*2)-(IF(I89=1, 0.5, 0))-J89+K89 -> 6
A90: Vasquez | B90: =IFERROR(INDEX(Fantacalcio!D:D, MATCH($A90, Fantacalcio!$C:$C, 0)), 0) -> 5.5 | C90: =IFERROR(INDEX(Fantacalcio!E:E, MATCH($A90, Fantacalcio!$C:$C, 0)), 0) -> 0 | D90: =IFERROR(INDEX(Fantacalcio!F:F, MATCH($A90, Fantacalcio!$C:$C, 0)), 0) -> 0 | E90: =IFERROR(INDEX(Fantacalcio!G:G, MATCH($A90, Fantacalcio!$C:$C, 0)), 0) -> 0 | F90: =IFERROR(INDEX(Fantacalcio!H:H, MATCH($A90, Fantacalcio!$C:$C, 0)), 0) -> 0 | G90: =IFERROR(INDEX(Fantacalcio!I:I, MATCH($A90, Fantacalcio!$C:$C, 0)), 0) -> 0 | H90: =IFERROR(INDEX(Fantacalcio!J:J, MATCH($A90, Fantacalcio!$C:$C, 0)), 0) -> 1 | I90: =IFERROR(INDEX(Fantacalcio!K:K, MATCH($A90, Fantacalcio!$C:$C, 0)), 0) -> 1 | J90: =IFERROR(INDEX(Fantacalcio!L:L, MATCH($A90, Fantacalcio!$C:$C, 0)), 0) -> 0 | K90: =IFERROR(INDEX(Fantacalcio!M:M, MATCH($A90, Fantacalcio!$C:$C, 0)), 0) -> 0 | L90: =B90+(C90*3)-D90+(E90*3)-(F90*3)+(G90*3)-(H90*2)-(IF(I90=1, 0.5, 0))-J90+K90 -> 3
A91: Valeri | B91: =IFERROR(INDEX(Fantacalcio!D:D, MATCH($A91, Fantacalcio!$C:$C, 0)), 0) -> 5 | C91: =IFERROR(INDEX(Fantacalcio!E:E, MATCH($A91, Fantacalcio!$C:$C, 0)), 0) -> 0 | D91: =IFERROR(INDEX(Fantacalcio!F:F, MATCH($A91, Fantacalcio!$C:$C, 0)), 0) -> 0 | E91: =IFERROR(INDEX(Fantacalcio!G:G, MATCH($A91, Fantacalcio!$C:$C, 0)), 0) -> 0 | F91: =IFERROR(INDEX(Fantacalcio!H:H, MATCH($A91, Fantacalcio!$C:$C, 0)), 0) -> 0 | G91: =IFERROR(INDEX(Fantacalcio!I:I, MATCH($A91, Fantacalcio!$C:$C, 0)), 0) -> 0 | H91: =IFERROR(INDEX(Fantacalcio!J:J, MATCH($A91, Fantacalcio!$C:$C, 0)), 0) -> 0 | I91: =IFERROR(INDEX(Fantacalcio!K:K, MATCH($A91, Fantacalcio!$C:$C, 0)), 0) -> 0 | J91: =IFERROR(INDEX(Fantacalcio!L:L, MATCH($A91, Fantacalcio!$C:$C, 0)), 0) -> 0 | K91: =IFERROR(INDEX(Fantacalcio!M:M, MATCH($A91, Fantacalcio!$C:$C, 0)), 0) -> 0 | L91: =B91+(C91*3)-D91+(E91*3)-(F91*3)+(G91*3)-(H91*2)-(IF(I91=1, 0.5, 0))-J91+K91 -> 5
A92: Vojvoda | B92: =IFERROR(INDEX(Fantacalcio!D:D, MATCH($A92, Fantacalcio!$C:$C, 0)), 0) -> 5.5 | C92: =IFERROR(INDEX(Fantacalcio!E:E, MATCH($A92, Fantacalcio!$C:$C, 0)), 0) -> 0 | D92: =IFERROR(INDEX(Fantacalcio!F:F, MATCH($A92, Fantacalcio!$C:$C, 0)), 0) -> 0 | E92: =IFERROR(INDEX(Fantacalcio!G:G, MATCH($A92, Fantacalcio!$C:$C, 0)), 0) -> 0 | F92: =IFERROR(INDEX(Fantacalcio!H:H, MATCH($A92, Fantacalcio!$C:$C, 0)), 0) -> 0 | G92: =IFERROR(INDEX(Fantacalcio!I:I, MATCH($A92, Fantacalcio!$C:$C, 0)), 0) -> 0 | H92: =IFERROR(INDEX(Fantacalcio!J:J, MATCH($A92, Fantacalcio!$C:$C, 0)), 0) -> 0 | I92: =IFERROR(INDEX(Fantacalcio!K:K, MATCH($A92, Fantacalcio!$C:$C, 0)), 0) -> 0 | J92: =IFERROR(INDEX(Fantacalcio!L:L, MATCH($A92, Fantacalcio!$C:$C, 0)), 0) -> 0 | K92: =IFERROR(INDEX(Fantacalcio!M:M, MATCH($A92, Fantacalcio!$C:$C, 0)), 0) -> 0 | L92: =B92+(C92*3)-D92+(E92*3)-(F92*3)+(G92*3)-(H92*2)-(IF(I92=1, 0.5, 0))-J92+K92 -> 5.5
A93: Couto | B93: =IFERROR(INDEX(Fantacalcio!D:D, MATCH($A93, Fantacalcio!$C:$C, 0)), 0) -> 6 | C93: =IFERROR(INDEX(Fantacalcio!E:E, MATCH($A93, Fantacalcio!$C:$C, 0)), 0) -> 0 | D93: =IFERROR(INDEX(Fantacalcio!F:F, MATCH($A93, Fantacalcio!$C:$C, 0)), 0) -> 0 | E93: =IFERROR(INDEX(Fantacalcio!G:G, MATCH($A93, Fantacalcio!$C:$C, 0)), 0) -> 0 | F93: =IFERROR(INDEX(Fantacalcio!H:H, MATCH($A93, Fantacalcio!$C:$C, 0)), 0) -> 0 | G93: =IFERROR(INDEX(Fantacalcio!I:I, MATCH($A93, Fantacalcio!$C:$C, 0)), 0) -> 0 | H93: =IFERROR(INDEX(Fantacalcio!J:J, MATCH($A93, Fantacalcio!$C:$C, 0)), 0) -> 0 | I93: =IFERROR(INDEX(Fantacalcio!K:K, MATCH($A93, Fantacalcio!$C:$C, 0)), 0) -> 0 | J93: =IFERROR(INDEX(Fantacalcio!L:L, MATCH($A93, Fantacalcio!$C:$C, 0)), 0) -> 0 | K93: =IFERROR(INDEX(Fantacalcio!M:M, MATCH($A93, Fantacalcio!$C:$C, 0)), 0) -> 0 | L93: =B93+(C93*3)-D93+(E93*3)-(F93*3)+(G93*3)-(H93*2)-(IF(I93=1, 0.5, 0))-J93+K93 -> 6
A94: Zappacosta | B94: =IFERROR(INDEX(Fantacalcio!D:D, MATCH($A94, Fantacalcio!$C:$C, 0)), 0) -> 5.5 | C94: =IFERROR(INDEX(Fantacalcio!E:E, MATCH($A94, Fantacalcio!$C:$C, 0)), 0) -> 0 | D94: =IFERROR(INDEX(Fantacalcio!F:F, MATCH($A94, Fantacalcio!$C:$C, 0)), 0) -> 0 | E94: =IFERROR(INDEX(Fantacalcio!G:G, MATCH($A94, Fantacalcio!$C:$C, 0)), 0) -> 0 | F94: =IFERROR(INDEX(Fantacalcio!H:H, MATCH($A94, Fantacalcio!$C:$C, 0)), 0) -> 0 | G94: =IFERROR(INDEX(Fantacalcio!I:I, MATCH($A94, Fantacalcio!$C:$C, 0)), 0) -> 0 | H94: =IFERROR(INDEX(Fantacalcio!J:J, MATCH($A94, Fantacalcio!$C:$C, 0)), 0) -> 0 | I94: =IFERROR(INDEX(Fantacalcio!K:K, MATCH($A94, Fantacalcio!$C:$C, 0)), 0) -> 0 | J94: =IFERROR(INDEX(Fantacalcio!L:L, MATCH($A94, Fantacalcio!$C:$C, 0)), 0) -> 0 | K94: =IFERROR(INDEX(Fantacalcio!M:M, MATCH($A94, Fantacalcio!$C:$C, 0)), 0) -> 0 | L94: =B94+(C94*3)-D94+(E94*3)-(F94*3)+(G94*3)-(H94*2)-(IF(I94=1, 0.5, 0))-J94+K94 -> 5.5
A95: Lucumì | B95: =IFERROR(INDEX(Fantacalcio!D:D, MATCH($A95, Fantacalcio!$C:$C, 0)), 0) -> 5.5 | C95: =IFERROR(INDEX(Fantacalcio!E:E, MATCH($A95, Fantacalcio!$C:$C, 0)), 0) -> 0 | D95: =IFERROR(INDEX(Fantacalcio!F:F, MATCH($A95, Fantacalcio!$C:$C, 0)), 0) -> 0 | E95: =IFERROR(INDEX(Fantacalcio!G:G, MATCH($A95, Fantacalcio!$C:$C, 0)), 0) -> 0 | F95: =IFERROR(INDEX(Fantacalcio!H:H, MATCH($A95, Fantacalcio!$C:$C, 0)), 0) -> 0 | G95: =IFERROR(INDEX(Fantacalcio!I:I, MATCH($A95, Fantacalcio!$C:$C, 0)), 0) -> 0 | H95: =IFERROR(INDEX(Fantacalcio!J:J, MATCH($A95, Fantacalcio!$C:$C, 0)), 0) -> 0 | I95: =IFERROR(INDEX(Fantacalcio!K:K, MATCH($A95, Fantacalcio!$C:$C, 0)), 0) -> 0 | J95: =IFERROR(INDEX(Fantacalcio!L:L, MATCH($A95, Fantacalcio!$C:$C, 0)), 0) -> 0 | K95: =IFERROR(INDEX(Fantacalcio!M:M, MATCH($A95, Fantacalcio!$C:$C, 0)), 0) -> 0 | L95: =B95+(C95*3)-D95+(E95*3)-(F95*3)+(G95*3)-(H95*2)-(IF(I95=1, 0.5, 0))-J95+K95 -> 5.5
A96: Obert | B96: =IFERROR(INDEX(Fantacalcio!D:D, MATCH($A96, Fantacalcio!$C:$C, 0)), 0) -> 5.5 | C96: =IFERROR(INDEX(Fantacalcio!E:E, MATCH($A96, Fantacalcio!$C:$C, 0)), 0) -> 0 | D96: =IFERROR(INDEX(Fantacalcio!F:F, MATCH($A96, Fantacalcio!$C:$C, 0)), 0) -> 0 | E96: =IFERROR(INDEX(Fantacalcio!G:G, MATCH($A96, Fantacalcio!$C:$C, 0)), 0) -> 0 | F96: =IFERROR(INDEX(Fantacalcio!H:H, MATCH($A96, Fantacalcio!$C:$C, 0)), 0) -> 0 | G96: =IFERROR(INDEX(Fantacalcio!I:I, MATCH($A96, Fantacalcio!$C:$C, 0)), 0) -> 0 | H96: =IFERROR(INDEX(Fantacalcio!J:J, MATCH($A96, Fantacalcio!$C:$C, 0)), 0) -> 0 | I96: =IFERROR(INDEX(Fantacalcio!K:K, MATCH($A96, Fantacalcio!$C:$C, 0)), 0) -> 0 | J96: =IFERROR(INDEX(Fantacalcio!L:L, MATCH($A96, Fantacalcio!$C:$C, 0)), 0) -> 0 | K96: =IFERROR(INDEX(Fantacalcio!M:M, MATCH($A96, Fantacalcio!$C:$C, 0)), 0) -> 0 | L96: =B96+(C96*3)-D96+(E96*3)-(F96*3)+(G96*3)-(H96*2)-(IF(I96=1, 0.5, 0))-J96+K96 -> 5.5
A97: Bracaglia | B97: =IFERROR(INDEX(Fantacalcio!D:D, MATCH($A97, Fantacalcio!$C:$C, 0)), 0) -> 6 | C97: =IFERROR(INDEX(Fantacalcio!E:E, MATCH($A97, Fantacalcio!$C:$C, 0)), 0) -> 0 | D97: =IFERROR(INDEX(Fantacalcio!F:F, MATCH($A97, Fantacalcio!$C:$C, 0)), 0) -> 0 | E97: =IFERROR(INDEX(Fantacalcio!G:G, MATCH($A97, Fantacalcio!$C:$C, 0)), 0) -> 0 | F97: =IFERROR(INDEX(Fantacalcio!H:H, MATCH($A97, Fantacalcio!$C:$C, 0)), 0) -> 0 | G97: =IFERROR(INDEX(Fantacalcio!I:I, MATCH($A97, Fantacalcio!$C:$C, 0)), 0) -> 0 | H97: =IFERROR(INDEX(Fantacalcio!J:J, MATCH($A97, Fantacalcio!$C:$C, 0)), 0) -> 0 | I97: =IFERROR(INDEX(Fantacalcio!K:K, MATCH($A97, Fantacalcio!$C:$C, 0)), 0) -> 0 | J97: =IFERROR(INDEX(Fantacalcio!L:L, MATCH($A97, Fantacalcio!$C:$C, 0)), 0) -> 0 | K97: =IFERROR(INDEX(Fantacalcio!M:M, MATCH($A97, Fantacalcio!$C:$C, 0)), 0) -> 0 | L97: =B97+(C97*3)-D97+(E97*3)-(F97*3)+(G97*3)-(H97*2)-(IF(I97=1, 0.5, 0))-J97+K97 -> 6
A98: Celik | B98: =IFERROR(INDEX(Fantacalcio!D:D, MATCH($A98, Fantacalcio!$C:$C, 0)), 0) -> 6 | C98: =IFERROR(INDEX(Fantacalcio!E:E, MATCH($A98, Fantacalcio!$C:$C, 0)), 0) -> 0 | D98: =IFERROR(INDEX(Fantacalcio!F:F, MATCH($A98, Fantacalcio!$C:$C, 0)), 0) -> 0 | E98: =IFERROR(INDEX(Fantacalcio!G:G, MATCH($A98, Fantacalcio!$C:$C, 0)), 0) -> 0 | F98: =IFERROR(INDEX(Fantacalcio!H:H, MATCH($A98, Fantacalcio!$C:$C, 0)), 0) -> 0 | G98: =IFERROR(INDEX(Fantacalcio!I:I, MATCH($A98, Fantacalcio!$C:$C, 0)), 0) -> 0 | H98: =IFERROR(INDEX(Fantacalcio!J:J, MATCH($A98, Fantacalcio!$C:$C, 0)), 0) -> 0 | I98: =IFERROR(INDEX(Fantacalcio!K:K, MATCH($A98, Fantacalcio!$C:$C, 0)), 0) -> 0 | J98: =IFERROR(INDEX(Fantacalcio!L:L, MATCH($A98, Fantacalcio!$C:$C, 0)), 0) -> 0 | K98: =IFERROR(INDEX(Fantacalcio!M:M, MATCH($A98, Fantacalcio!$C:$C, 0)), 0) -> 0 | L98: =B98+(C98*3)-D98+(E98*3)-(F98*3)+(G98*3)-(H98*2)-(IF(I98=1, 0.5, 0))-J98+K98 -> 6
A99: Cambiaso | B99: =IFERROR(INDEX(Fantacalcio!D:D, MATCH($A99, Fantacalcio!$C:$C, 0)), 0) -> 5.5 | C99: =IFERROR(INDEX(Fantacalcio!E:E, MATCH($A99, Fantacalcio!$C:$C, 0)), 0) -> 0 | D99: =IFERROR(INDEX(Fantacalcio!F:F, MATCH($A99, Fantacalcio!$C:$C, 0)), 0) -> 0 | E99: =IFERROR(INDEX(Fantacalcio!G:G, MATCH($A99, Fantacalcio!$C:$C, 0)), 0) -> 0 | F99: =IFERROR(INDEX(Fantacalcio!H:H, MATCH($A99, Fantacalcio!$C:$C, 0)), 0) -> 0 | G99: =IFERROR(INDEX(Fantacalcio!I:I, MATCH($A99, Fantacalcio!$C:$C, 0)), 0) -> 0 | H99: =IFERROR(INDEX(Fantacalcio!J:J, MATCH($A99, Fantacalcio!$C:$C, 0)), 0) -> 0 | I99: =IFERROR(INDEX(Fantacalcio!K:K, MATCH($A99, Fantacalcio!$C:$C, 0)), 0) -> 0 | J99: =IFERROR(INDEX(Fantacalcio!L:L, MATCH($A99, Fantacalcio!$C:$C, 0)), 0) -> 0 | K99: =IFERROR(INDEX(Fantacalcio!M:M, MATCH($A99, Fantacalcio!$C:$C, 0)), 0) -> 0 | L99: =B99+(C99*3)-D99+(E99*3)-(F99*3)+(G99*3)-(H99*2)-(IF(I99=1, 0.5, 0))-J99+K99 -> 5.5
A100: Doekhi | B100: =IFERROR(INDEX(Fantacalcio!D:D, MATCH($A100, Fantacalcio!$C:$C, 0)), 0) -> 6 | C100: =IFERROR(INDEX(Fantacalcio!E:E, MATCH($A100, Fantacalcio!$C:$C, 0)), 0) -> 0 | D100: =IFERROR(INDEX(Fantacalcio!F:F, MATCH($A100, Fantacalcio!$C:$C, 0)), 0) -> 0 | E100: =IFERROR(INDEX(Fantacalcio!G:G, MATCH($A100, Fantacalcio!$C:$C, 0)), 0) -> 0 | F100: =IFERROR(INDEX(Fantacalcio!H:H, MATCH($A100, Fantacalcio!$C:$C, 0)), 0) -> 0 | G100: =IFERROR(INDEX(Fantacalcio!I:I, MATCH($A100, Fantacalcio!$C:$C, 0)), 0) -> 0 | H100: =IFERROR(INDEX(Fantacalcio!J:J, MATCH($A100, Fantacalcio!$C:$C, 0)), 0) -> 0 | I100: =IFERROR(INDEX(Fantacalcio!K:K, MATCH($A100, Fantacalcio!$C:$C, 0)), 0) -> 1 | J100: =IFERROR(INDEX(Fantacalcio!L:L, MATCH($A100, Fantacalcio!$C:$C, 0)), 0) -> 0 | K100: =IFERROR(INDEX(Fantacalcio!M:M, MATCH($A100, Fantacalcio!$C:$C, 0)), 0) -> 0 | L100: =B100+(C100*3)-D100+(E100*3)-(F100*3)+(G100*3)-(H100*2)-(IF(I100=1, 0.5, 0))-J100+K100 -> 5.5
A101: Tiago Gabriel | B101: =IFERROR(INDEX(Fantacalcio!D:D, MATCH($A101, Fantacalcio!$C:$C, 0)), 0) -> 5.5 | C101: =IFERROR(INDEX(Fantacalcio!E:E, MATCH($A101, Fantacalcio!$C:$C, 0)), 0) -> 0 | D101: =IFERROR(INDEX(Fantacalcio!F:F, MATCH($A101, Fantacalcio!$C:$C, 0)), 0) -> 0 | E101: =IFERROR(INDEX(Fantacalcio!G:G, MATCH($A101, Fantacalcio!$C:$C, 0)), 0) -> 0 | F101: =IFERROR(INDEX(Fantacalcio!H:H, MATCH($A101, Fantacalcio!$C:$C, 0)), 0) -> 0 | G101: =IFERROR(INDEX(Fantacalcio!I:I, MATCH($A101, Fantacalcio!$C:$C, 0)), 0) -> 0 | H101: =IFERROR(INDEX(Fantacalcio!J:J, MATCH($A101, Fantacalcio!$C:$C, 0)), 0) -> 0 | I101: =IFERROR(INDEX(Fantacalcio!K:K, MATCH($A101, Fantacalcio!$C:$C, 0)), 0) -> 0 | J101: =IFERROR(INDEX(Fantacalcio!L:L, MATCH($A101, Fantacalcio!$C:$C, 0)), 0) -> 0 | K101: =IFERROR(INDEX(Fantacalcio!M:M, MATCH($A101, Fantacalcio!$C:$C, 0)), 0) -> 0 | L101: =B101+(C101*3)-D101+(E101*3)-(F101*3)+(G101*3)-(H101*2)-(IF(I101=1, 0.5, 0))-J101+K101 -> 5.5
... A151: Rodriguez Ju. | B151: =IFERROR(INDEX(Fantacalcio!D:D, MATCH($A151, Fantacalcio!$C:$C, 0)), 0) -> 6 | C151: =IFERROR(INDEX(Fantacalcio!E:E, MATCH($A151, Fantacalcio!$C:$C, 0)), 0) -> 0 | D151: =IFERROR(INDEX(Fantacalcio!F:F, MATCH($A151, Fantacalcio!$C:$C, 0)), 0) -> 0 | E151: =IFERROR(INDEX(Fantacalcio!G:G, MATCH($A151, Fantacalcio!$C:$C, 0)), 0) -> 0 | F151: =IFERROR(INDEX(Fantacalcio!H:H, MATCH($A151, Fantacalcio!$C:$C, 0)), 0) -> 0 | G151: =IFERROR(INDEX(Fantacalcio!I:I, MATCH($A151, Fantacalcio!$C:$C, 0)), 0) -> 0 | H151: =IFERROR(INDEX(Fantacalcio!J:J, MATCH($A151, Fantacalcio!$C:$C, 0)), 0) -> 0 | I151: =IFERROR(INDEX(Fantacalcio!K:K, MATCH($A151, Fantacalcio!$C:$C, 0)), 0) -> 1 | J151: =IFERROR(INDEX(Fantacalcio!L:L, MATCH($A151, Fantacalcio!$C:$C, 0)), 0) -> 0 | K151: =IFERROR(INDEX(Fantacalcio!M:M, MATCH($A151, Fantacalcio!$C:$C, 0)), 0) -> 0 | L151: =B151+(C151*3)-D151+(E151*3)-(F151*3)+(G151*3)-(H151*2)-(IF(I151=1, 0.5, 0))-J151+K151 -> 5.5
A152: Kempf | B152: 6 | C152: =IFERROR(INDEX(Fantacalcio!E:E, MATCH($A152, Fantacalcio!$C:$C, 0)), 0) -> 0 | D152: =IFERROR(INDEX(Fantacalcio!F:F, MATCH($A152, Fantacalcio!$C:$C, 0)), 0) -> 0 | E152: =IFERROR(INDEX(Fantacalcio!G:G, MATCH($A152, Fantacalcio!$C:$C, 0)), 0) -> 0 | F152: =IFERROR(INDEX(Fantacalcio!H:H, MATCH($A152, Fantacalcio!$C:$C, 0)), 0) -> 0 | G152: =IFERROR(INDEX(Fantacalcio!I:I, MATCH($A152, Fantacalcio!$C:$C, 0)), 0) -> 0 | H152: =IFERROR(INDEX(Fantacalcio!J:J, MATCH($A152, Fantacalcio!$C:$C, 0)), 0) -> 0 | I152: =IFERROR(INDEX(Fantacalcio!K:K, MATCH($A152, Fantacalcio!$C:$C, 0)), 0) -> 0 | J152: =IFERROR(INDEX(Fantacalcio!L:L, MATCH($A152, Fantacalcio!$C:$C, 0)), 0) -> 0 | K152: =IFERROR(INDEX(Fantacalcio!M:M, MATCH($A152, Fantacalcio!$C:$C, 0)), 0) -> 0 | L152: =B152+(C152*3)-D152+(E152*3)-(F152*3)+(G152*3)-(H152*2)-(IF(I152=1, 0.5, 0))-J152+K152 -> 6
A153: Valdepenas | B153: =IFERROR(INDEX(Fantacalcio!D:D, MATCH($A153, Fantacalcio!$C:$C, 0)), 0) -> 5.5 | C153: =IFERROR(INDEX(Fantacalcio!E:E, MATCH($A153, Fantacalcio!$C:$C, 0)), 0) -> 0 | D153: =IFERROR(INDEX(Fantacalcio!F:F, MATCH($A153, Fantacalcio!$C:$C, 0)), 0) -> 0 | E153: =IFERROR(INDEX(Fantacalcio!G:G, MATCH($A153, Fantacalcio!$C:$C, 0)), 0) -> 0 | F153: =IFERROR(INDEX(Fantacalcio!H:H, MATCH($A153, Fantacalcio!$C:$C, 0)), 0) -> 0 | G153: =IFERROR(INDEX(Fantacalcio!I:I, MATCH($A153, Fantacalcio!$C:$C, 0)), 0) -> 0 | H153: =IFERROR(INDEX(Fantacalcio!J:J, MATCH($A153, Fantacalcio!$C:$C, 0)), 0) -> 0 | I153: =IFERROR(INDEX(Fantacalcio!K:K, MATCH($A153, Fantacalcio!$C:$C, 0)), 0) -> 0 | J153: =IFERROR(INDEX(Fantacalcio!L:L, MATCH($A153, Fantacalcio!$C:$C, 0)), 0) -> 0 | K153: =IFERROR(INDEX(Fantacalcio!M:M, MATCH($A153, Fantacalcio!$C:$C, 0)), 0) -> 0 | L153: =B153+(C153*3)-D153+(E153*3)-(F153*3)+(G153*3)-(H153*2)-(IF(I153=1, 0.5, 0))-J153+K153 -> 5.5
A154: Viery | B154: =IFERROR(INDEX(Fantacalcio!D:D, MATCH($A154, Fantacalcio!$C:$C, 0)), 0) -> 5.5 | C154: =IFERROR(INDEX(Fantacalcio!E:E, MATCH($A154, Fantacalcio!$C:$C, 0)), 0) -> 0 | D154: =IFERROR(INDEX(Fantacalcio!F:F, MATCH($A154, Fantacalcio!$C:$C, 0)), 0) -> 0 | E154: =IFERROR(INDEX(Fantacalcio!G:G, MATCH($A154, Fantacalcio!$C:$C, 0)), 0) -> 0 | F154: =IFERROR(INDEX(Fantacalcio!H:H, MATCH($A154, Fantacalcio!$C:$C, 0)), 0) -> 0 | G154: =IFERROR(INDEX(Fantacalcio!I:I, MATCH($A154, Fantacalcio!$C:$C, 0)), 0) -> 0 | H154: =IFERROR(INDEX(Fantacalcio!J:J, MATCH($A154, Fantacalcio!$C:$C, 0)), 0) -> 0 | I154: =IFERROR(INDEX(Fantacalcio!K:K, MATCH($A154, Fantacalcio!$C:$C, 0)), 0) -> 1 | J154: =IFERROR(INDEX(Fantacalcio!L:L, MATCH($A154, Fantacalcio!$C:$C, 0)), 0) -> 0 | K154: =IFERROR(INDEX(Fantacalcio!M:M, MATCH($A154, Fantacalcio!$C:$C, 0)), 0) -> 0 | L154: =B154+(C154*3)-D154+(E154*3)-(F154*3)+(G154*3)-(H154*2)-(IF(I154=1, 0.5, 0))-J154+K154 -> 5
A155: Gatti | B155: =IFERROR(INDEX(Fantacalcio!D:D, MATCH($A155, Fantacalcio!$C:$C, 0)), 0) -> 0 | C155: =IFERROR(INDEX(Fantacalcio!E:E, MATCH($A155, Fantacalcio!$C:$C, 0)), 0) -> 0 | D155: =IFERROR(INDEX(Fantacalcio!F:F, MATCH($A155, Fantacalcio!$C:$C, 0)), 0) -> 0 | E155: =IFERROR(INDEX(Fantacalcio!G:G, MATCH($A155, Fantacalcio!$C:$C, 0)), 0) -> 0 | F155: =IFERROR(INDEX(Fantacalcio!H:H, MATCH($A155, Fantacalcio!$C:$C, 0)), 0) -> 0 | G155: =IFERROR(INDEX(Fantacalcio!I:I, MATCH($A155, Fantacalcio!$C:$C, 0)), 0) -> 0 | H155: =IFERROR(INDEX(Fantacalcio!J:J, MATCH($A155, Fantacalcio!$C:$C, 0)), 0) -> 0 | I155: =IFERROR(INDEX(Fantacalcio!K:K, MATCH($A155, Fantacalcio!$C:$C, 0)), 0) -> 0 | J155: =IFERROR(INDEX(Fantacalcio!L:L, MATCH($A155, Fantacalcio!$C:$C, 0)), 0) -> 0 | K155: =IFERROR(INDEX(Fantacalcio!M:M, MATCH($A155, Fantacalcio!$C:$C, 0)), 0) -> 0 | L155: =B155+(C155*3)-D155+(E155*3)-(F155*3)+(G155*3)-(H155*2)-(IF(I155=1, 0.5, 0))-J155+K155 -> 0
A156: Kelly L. | B156: =IFERROR(INDEX(Fantacalcio!D:D, MATCH($A156, Fantacalcio!$C:$C, 0)), 0) -> 0 | C156: =IFERROR(INDEX(Fantacalcio!E:E, MATCH($A156, Fantacalcio!$C:$C, 0)), 0) -> 0 | D156: =IFERROR(INDEX(Fantacalcio!F:F, MATCH($A156, Fantacalcio!$C:$C, 0)), 0) -> 0 | E156: =IFERROR(INDEX(Fantacalcio!G:G, MATCH($A156, Fantacalcio!$C:$C, 0)), 0) -> 0 | F156: =IFERROR(INDEX(Fantacalcio!H:H, MATCH($A156, Fantacalcio!$C:$C, 0)), 0) -> 0 | G156: =IFERROR(INDEX(Fantacalcio!I:I, MATCH($A156, Fantacalcio!$C:$C, 0)), 0) -> 0 | H156: =IFERROR(INDEX(Fantacalcio!J:J, MATCH($A156, Fantacalcio!$C:$C, 0)), 0) -> 0 | I156: =IFERROR(INDEX(Fantacalcio!K:K, MATCH($A156, Fantacalcio!$C:$C, 0)), 0) -> 0 | J156: =IFERROR(INDEX(Fantacalcio!L:L, MATCH($A156, Fantacalcio!$C:$C, 0)), 0) -> 0 | K156: =IFERROR(INDEX(Fantacalcio!M:M, MATCH($A156, Fantacalcio!$C:$C, 0)), 0) -> 0 | L156: =B156+(C156*3)-D156+(E156*3)-(F156*3)+(G156*3)-(H156*2)-(IF(I156=1, 0.5, 0))-J156+K156 -> 0
A157: Gaspar K. | B157: =IFERROR(INDEX(Fantacalcio!D:D, MATCH($A157, Fantacalcio!$C:$C, 0)), 0) -> 0 | C157: =IFERROR(INDEX(Fantacalcio!E:E, MATCH($A157, Fantacalcio!$C:$C, 0)), 0) -> 0 | D157: =IFERROR(INDEX(Fantacalcio!F:F, MATCH($A157, Fantacalcio!$C:$C, 0)), 0) -> 0 | E157: =IFERROR(INDEX(Fantacalcio!G:G, MATCH($A157, Fantacalcio!$C:$C, 0)), 0) -> 0 | F157: =IFERROR(INDEX(Fantacalcio!H:H, MATCH($A157, Fantacalcio!$C:$C, 0)), 0) -> 0 | G157: =IFERROR(INDEX(Fantacalcio!I:I, MATCH($A157, Fantacalcio!$C:$C, 0)), 0) -> 0 | H157: =IFERROR(INDEX(Fantacalcio!J:J, MATCH($A157, Fantacalcio!$C:$C, 0)), 0) -> 0 | I157: =IFERROR(INDEX(Fantacalcio!K:K, MATCH($A157, Fantacalcio!$C:$C, 0)), 0) -> 0 | J157: =IFERROR(INDEX(Fantacalcio!L:L, MATCH($A157, Fantacalcio!$C:$C, 0)), 0) -> 0 | K157: =IFERROR(INDEX(Fantacalcio!M:M, MATCH($A157, Fantacalcio!$C:$C, 0)), 0) -> 0 | L157: =B157+(C157*3)-D157+(E157*3)-(F157*3)+(G157*3)-(H157*2)-(IF(I157=1, 0.5, 0))-J157+K157 -> 0
A158: Veiga D. | B158: =IFERROR(INDEX(Fantacalcio!D:D, MATCH($A158, Fantacalcio!$C:$C, 0)), 0) -> 6 | C158: =IFERROR(INDEX(Fantacalcio!E:E, MATCH($A158, Fantacalcio!$C:$C, 0)), 0) -> 0 | D158: =IFERROR(INDEX(Fantacalcio!F:F, MATCH($A158, Fantacalcio!$C:$C, 0)), 0) -> 0 | E158: =IFERROR(INDEX(Fantacalcio!G:G, MATCH($A158, Fantacalcio!$C:$C, 0)), 0) -> 0 | F158: =IFERROR(INDEX(Fantacalcio!H:H, MATCH($A158, Fantacalcio!$C:$C, 0)), 0) -> 0 | G158: =IFERROR(INDEX(Fantacalcio!I:I, MATCH($A158, Fantacalcio!$C:$C, 0)), 0) -> 0 | H158: =IFERROR(INDEX(Fantacalcio!J:J, MATCH($A158, Fantacalcio!$C:$C, 0)), 0) -> 0 | I158: =IFERROR(INDEX(Fantacalcio!K:K, MATCH($A158, Fantacalcio!$C:$C, 0)), 0) -> 0 | J158: =IFERROR(INDEX(Fantacalcio!L:L, MATCH($A158, Fantacalcio!$C:$C, 0)), 0) -> 0 | K158: =IFERROR(INDEX(Fantacalcio!M:M, MATCH($A158, Fantacalcio!$C:$C, 0)), 0) -> 1 | L158: =B158+(C158*3)-D158+(E158*3)-(F158*3)+(G158*3)-(H158*2)-(IF(I158=1, 0.5, 0))-J158+K158 -> 7
A159: Gallo | B159: =IFERROR(INDEX(Fantacalcio!D:D, MATCH($A159, Fantacalcio!$C:$C, 0)), 0) -> 5.5 | C159: =IFERROR(INDEX(Fantacalcio!E:E, MATCH($A159, Fantacalcio!$C:$C, 0)), 0) -> 0 | D159: =IFERROR(INDEX(Fantacalcio!F:F, MATCH($A159, Fantacalcio!$C:$C, 0)), 0) -> 0 | E159: =IFERROR(INDEX(Fantacalcio!G:G, MATCH($A159, Fantacalcio!$C:$C, 0)), 0) -> 0 | F159: =IFERROR(INDEX(Fantacalcio!H:H, MATCH($A159, Fantacalcio!$C:$C, 0)), 0) -> 0 | G159: =IFERROR(INDEX(Fantacalcio!I:I, MATCH($A159, Fantacalcio!$C:$C, 0)), 0) -> 0 | H159: =IFERROR(INDEX(Fantacalcio!J:J, MATCH($A159, Fantacalcio!$C:$C, 0)), 0) -> 0 | I159: =IFERROR(INDEX(Fantacalcio!K:K, MATCH($A159, Fantacalcio!$C:$C, 0)), 0) -> 0 | J159: =IFERROR(INDEX(Fantacalcio!L:L, MATCH($A159, Fantacalcio!$C:$C, 0)), 0) -> 0 | K159: =IFERROR(INDEX(Fantacalcio!M:M, MATCH($A159, Fantacalcio!$C:$C, 0)), 0) -> 0 | L159: =B159+(C159*3)-D159+(E159*3)-(F159*3)+(G159*3)-(H159*2)-(IF(I159=1, 0.5, 0))-J159+K159 -> 5.5
A160: De Winter | B160: =IFERROR(INDEX(Fantacalcio!D:D, MATCH($A160, Fantacalcio!$C:$C, 0)), 0) -> 6 | C160: =IFERROR(INDEX(Fantacalcio!E:E, MATCH($A160, Fantacalcio!$C:$C, 0)), 0) -> 0 | D160: =IFERROR(INDEX(Fantacalcio!F:F, MATCH($A160, Fantacalcio!$C:$C, 0)), 0) -> 0 | E160: =IFERROR(INDEX(Fantacalcio!G:G, MATCH($A160, Fantacalcio!$C:$C, 0)), 0) -> 0 | F160: =IFERROR(INDEX(Fantacalcio!H:H, MATCH($A160, Fantacalcio!$C:$C, 0)), 0) -> 0 | G160: =IFERROR(INDEX(Fantacalcio!I:I, MATCH($A160, Fantacalcio!$C:$C, 0)), 0) -> 0 | H160: =IFERROR(INDEX(Fantacalcio!J:J, MATCH($A160, Fantacalcio!$C:$C, 0)), 0) -> 0 | I160: =IFERROR(INDEX(Fantacalcio!K:K, MATCH($A160, Fantacalcio!$C:$C, 0)), 0) -> 1 | J160: =IFERROR(INDEX(Fantacalcio!L:L, MATCH($A160, Fantacalcio!$C:$C, 0)), 0) -> 0 | K160: =IFERROR(INDEX(Fantacalcio!M:M, MATCH($A160, Fantacalcio!$C:$C, 0)), 0) -> 0 | L160: =B160+(C160*3)-D160+(E160*3)-(F160*3)+(G160*3)-(H160*2)-(IF(I160=1, 0.5, 0))-J160+K160 -> 5.5
A161: Birindelli | B161: =IFERROR(INDEX(Fantacalcio!D:D, MATCH($A161, Fantacalcio!$C:$C, 0)), 0) -> 5 | C161: =IFERROR(INDEX(Fantacalcio!E:E, MATCH($A161, Fantacalcio!$C:$C, 0)), 0) -> 0 | D161: =IFERROR(INDEX(Fantacalcio!F:F, MATCH($A161, Fantacalcio!$C:$C, 0)), 0) -> 0 | E161: =IFERROR(INDEX(Fantacalcio!G:G, MATCH($A161, Fantacalcio!$C:$C, 0)), 0) -> 0 | F161: =IFERROR(INDEX(Fantacalcio!H:H, MATCH($A161, Fantacalcio!$C:$C, 0)), 0) -> 0 | G161: =IFERROR(INDEX(Fantacalcio!I:I, MATCH($A161, Fantacalcio!$C:$C, 0)), 0) -> 0 | H161: =IFERROR(INDEX(Fantacalcio!J:J, MATCH($A161, Fantacalcio!$C:$C, 0)), 0) -> 0 | I161: =IFERROR(INDEX(Fantacalcio!K:K, MATCH($A161, Fantacalcio!$C:$C, 0)), 0) -> 0 | J161: =IFERROR(INDEX(Fantacalcio!L:L, MATCH($A161, Fantacalcio!$C:$C, 0)), 0) -> 0 | K161: =IFERROR(INDEX(Fantacalcio!M:M, MATCH($A161, Fantacalcio!$C:$C, 0)), 0) -> 0 | L161: =B161+(C161*3)-D161+(E161*3)-(F161*3)+(G161*3)-(H161*2)-(IF(I161=1, 0.5, 0))-J161+K161 -> 5
A162: Beukema | B162: =IFERROR(INDEX(Fantacalcio!D:D, MATCH($A162, Fantacalcio!$C:$C, 0)), 0) -> 0 | C162: =IFERROR(INDEX(Fantacalcio!E:E, MATCH($A162, Fantacalcio!$C:$C, 0)), 0) -> 0 | D162: =IFERROR(INDEX(Fantacalcio!F:F, MATCH($A162, Fantacalcio!$C:$C, 0)), 0) -> 0 | E162: =IFERROR(INDEX(Fantacalcio!G:G, MATCH($A162, Fantacalcio!$C:$C, 0)), 0) -> 0 | F162: =IFERROR(INDEX(Fantacalcio!H:H, MATCH($A162, Fantacalcio!$C:$C, 0)), 0) -> 0 | G162: =IFERROR(INDEX(Fantacalcio!I:I, MATCH($A162, Fantacalcio!$C:$C, 0)), 0) -> 0 | H162: =IFERROR(INDEX(Fantacalcio!J:J, MATCH($A162, Fantacalcio!$C:$C, 0)), 0) -> 0 | I162: =IFERROR(INDEX(Fantacalcio!K:K, MATCH($A162, Fantacalcio!$C:$C, 0)), 0) -> 0 | J162: =IFERROR(INDEX(Fantacalcio!L:L, MATCH($A162, Fantacalcio!$C:$C, 0)), 0) -> 0 | K162: =IFERROR(INDEX(Fantacalcio!M:M, MATCH($A162, Fantacalcio!$C:$C, 0)), 0) -> 0 | L162: =B162+(C162*3)-D162+(E162*3)-(F162*3)+(G162*3)-(H162*2)-(IF(I162=1, 0.5, 0))-J162+K162 -> 0
A163: Ghilardi | B163: =IFERROR(INDEX(Fantacalcio!D:D, MATCH($A163, Fantacalcio!$C:$C, 0)), 0) -> 0 | C163: =IFERROR(INDEX(Fantacalcio!E:E, MATCH($A163, Fantacalcio!$C:$C, 0)), 0) -> 0 | D163: =IFERROR(INDEX(Fantacalcio!F:F, MATCH($A163, Fantacalcio!$C:$C, 0)), 0) -> 0 | E163: =IFERROR(INDEX(Fantacalcio!G:G, MATCH($A163, Fantacalcio!$C:$C, 0)), 0) -> 0 | F163: =IFERROR(INDEX(Fantacalcio!H:H, MATCH($A163, Fantacalcio!$C:$C, 0)), 0) -> 0 | G163: =IFERROR(INDEX(Fantacalcio!I:I, MATCH($A163, Fantacalcio!$C:$C, 0)), 0) -> 0 | H163: =IFERROR(INDEX(Fantacalcio!J:J, MATCH($A163, Fantacalcio!$C:$C, 0)), 0) -> 0 | I163: =IFERROR(INDEX(Fantacalcio!K:K, MATCH($A163, Fantacalcio!$C:$C, 0)), 0) -> 0 | J163: =IFERROR(INDEX(Fantacalcio!L:L, MATCH($A163, Fantacalcio!$C:$C, 0)), 0) -> 0 | K163: =IFERROR(INDEX(Fantacalcio!M:M, MATCH($A163, Fantacalcio!$C:$C, 0)), 0) -> 0 | L163: =B163+(C163*3)-D163+(E163*3)-(F163*3)+(G163*3)-(H163*2)-(IF(I163=1, 0.5, 0))-J163+K163 -> 0
...

Sheet Fantacalcio
A1: Atalanta
A2: Cod. | B2: Ruolo | C2: Nome | D2: Voto | E2: Gf | F2: Gs | G2: Rp | H2: Rs | I2: Rf | J2: Au | K2: Amm | L2: Esp | M2: Ass
A3: 4431 | B3: P | C3: Carnesecchi | D3: 6 | E3: 0 | F3: 1 | G3: 0 | H3: 0 | I3: 0 | J3: 0 | K3: 0 | L3: 0 | M3: 0
A4: 554 | B4: D | C4: Zappacosta | D4: 5.5 | E4: 0 | F4: 0 | G4: 0 | H4: 0 | I4: 0 | J4: 0 | K4: 0 | L4: 0 | M4: 0
A5: 2640 | B5: D | C5: Kolasinac | D5: 6 | E5: 0 | F5: 0 | G5: 0 | H5: 0 | I5: 0 | J5: 0 | K5: 0 | L5: 0 | M5: 0
A6: 4887 | B6: D | C6: Bellanova | D6: 7 | E6: 0 | F6: 0 | G6: 0 | H6: 0 | I6: 0 | J6: 0 | K6: 0 | L6: 0 | M6: 0
A7: 5526 | B7: D | C7: Scalvini | D7: 6 | E7: 0 | F7: 0 | G7: 0 | H7: 0 | I7: 0 | J7: 0 | K7: 0 | L7: 0 | M7: 0
A8: 6485 | B8: D | C8: Kristensen T. | D8: 6 | E8: 0 | F8: 0 | G8: 0 | H8: 0 | I8: 0 | J8: 0 | K8: 0 | L8: 0 | M8: 0
A9: 7219 | B9: D | C9: Bernasconi | D9: 6 | E9: 0 | F9: 0 | G9: 0 | H9: 0 | I9: 0 | J9: 0 | K9: 0 | L9: 0 | M9: 0
A10: 1850 | B10: C | C10: Kessiè | D10: 7 | E10: 1 | F10: 0 | G10: 0 | H10: 0 | I10: 0 | J10: 0 | K10: 0 | L10: 0 | M10: 0
A11: 4364 | B11: C | C11: Gaetano | D11: 6* | E11: 0 | F11: 0 | G11: 0 | H11: 0 | I11: 0 | J11: 0 | K11: 0 | L11: 0 | M11: 0
A12: 4479 | B12: C | C12: Elmas | D12: 5.5 | E12: 0 | F12: 0 | G12: 0 | H12: 0 | I12: 0 | J12: 0 | K12: 0 | L12: 1 | M12: 1
A13: 5119 | B13: C | C13: Samardzic | D13: 6 | E13: 0 | F13: 0 | G13: 0 | H13: 0 | I13: 0 | J13: 0 | K13: 0 | L13: 0 | M13: 0
A14: 5422 | B14: C | C14: Zalewski | D14: 6* | E14: 0 | F14: 0 | G14: 0 | H14: 0 | I14: 0 | J14: 0 | K14: 0 | L14: 0 | M14: 0
A15: 5792 | B15: C | C15: Ederson D.S. | D15: 6 | E15: 0 | F15: 0 | G15: 0 | H15: 0 | I15: 0 | J15: 0 | K15: 0 | L15: 0 | M15: 0
A16: 6844 | B16: C | C16: Rowe | D16: 6 | E16: 0 | F16: 0 | G16: 0 | H16: 0 | I16: 0 | J16: 0 | K16: 0 | L16: 0 | M16: 0
A17: 5995 | B17: A | C17: De Ketelaere | D17: 6 | E17: 0 | F17: 0 | G17: 0 | H17: 0 | I17: 0 | J17: 0 | K17: 0 | L17: 0 | M17: 0
A18: 6435 | B18: A | C18: Krstovic | D18: 8 | E18: 2 | F18: 0 | G18: 0 | H18: 0 | I18: 0 | J18: 0 | K18: 0 | L18: 0 | M18: 1
A19: 688 | B19: ALL | C19: Sarri | D19: 6.5 | E19: 0 | F19: 0 | G19: 0 | H19: 0 | I19: 0 | J19: 0 | K19: 0 | L19: 0 | M19: 0
A20: Bologna
A21: Cod. | B21: Ruolo | C21: Nome | D21: Voto | E21: Gf | F21: Gs | G21: Rp | H21: Rs | I21: Rf | J21: Au | K21: Amm | L21: Esp | M21: Ass
A22: 7172 | B22: P | C22: Pessina Mas. | D22: 5 | E22: 0 | F22: 1 | G22: 0 | H22: 0 | I22: 0 | J22: 0 | K22: 0 | L22: 0 | M22: 0
A23: 2525 | B23: D | C23: Darmian | D23: 6 | E23: 0 | F23: 0 | G23: 0 | H23: 0 | I23: 0 | J23: 0 | K23: 0 | L23: 0 | M23: 0
A24: 4433 | B24: D | C24: Zortea | D24: 6 | E24: 0 | F24: 0 | G24: 0 | H24: 0 | I24: 0 | J24: 0 | K24: 0 | L24: 0 | M24: 0
A25: 4734 | B25: D | C25: Miranda J. | D25: 6.5 | E25: 0 | F25: 0 | G25: 0 | H25: 0 | I25: 0 | J25: 0 | K25: 0 | L25: 0 | M25: 0
A26: 5498 | B26: D | C26: Casale | D26: 6.5 | E26: 0 | F26: 0 | G26: 0 | H26: 0 | I26: 0 | J26: 0 | K26: 0 | L26: 0 | M26: 0
A27: 7212 | B27: D | C27: Heggem | D27: 6 | E27: 0 | F27: 0 | G27: 0 | H27: 0 | I27: 0 | J27: 0 | K27: 1 | L27: 0 | M27: 0
A28: 7326 | B28: D | C28: Helland | D28: 6 | E28: 0 | F28: 0 | G28: 0 | H28: 0 | I28: 0 | J28: 0 | K28: 0 | L28: 0 | M28: 0
A29: 7483 | B29: D | C29: Alhassane | D29: 6* | E29: 0 | F29: 0 | G29: 0 | H29: 0 | I29: 0 | J29: 0 | K29: 0 | L29: 0 | M29: 0
A30: 184 | B30: C | C30: Bernardeschi | D30: 6* | E30: 0 | F30: 0 | G30: 0 | H30: 0 | I30: 0 | J30: 0 | K30: 0 | L30: 0 | M30: 0
A31: 2167 | B31: C | C31: Orsolini | D31: 7.5 | E31: 1 | F31: 0 | G31: 0 | H31: 0 | I31: 0 | J31: 0 | K31: 0 | L31: 0 | M31: 0
A32: 4436 | B32: C | C32: Cambiaghi | D32: 7 | E32: 0 | F32: 0 | G32: 0 | H32: 0 | I32: 0 | J32: 0 | K32: 0 | L32: 0 | M32: 2
A33: 5298 | B33: C | C33: Pobega | D33: 6.5 | E33: 0 | F33: 0 | G33: 0 | H33: 0 | I33: 0 | J33: 0 | K33: 0 | L33: 0 | M33: 0
A34: 5858 | B34: C | C34: Ferguson | D34: 6.5 | E34: 0 | F34: 0 | G34: 0 | H34: 0 | I34: 0 | J34: 0 | K34: 0 | L34: 0 | M34: 0
A35: 6225 | B35: C | C35: El Azzouzi O. | D35: 6 | E35: 0 | F35: 0 | G35: 0 | H35: 0 | I35: 0 | J35: 0 | K35: 1 | L35: 0 | M35: 0
A36: 4359 | B36: A | C36: Piccoli | D36: 6.5 | E36: 0 | F36: 0 | G36: 0 | H36: 0 | I36: 0 | J36: 0 | K36: 0 | L36: 0 | M36: 0
A37: 7627 | B37: A | C37: Enem | D37: 7 | E37: 1 | F37: 0 | G37: 0 | H37: 0 | I37: 0 | J37: 0 | K37: 0 | L37: 0 | M37: 0
A38: 1909 | B38: ALL | C38: Palladino | D38: 6.5 | E38: 0 | F38: 0 | G38: 0 | H38: 0 | I38: 0 | J38: 0 | K38: 0 | L38: 0 | M38: 0
A39: Cagliari
A40: Cod. | B40: Ruolo | C40: Nome | D40: Voto | E40: Gf | F40: Gs | G40: Rp | H40: Rs | I40: Rf | J40: Au | K40: Amm | L40: Esp | M40: Ass
...
